Workbook

Sheet Revenue Decomposition
A1: Cleveland-Cliffs (CLF) — Revenue & Segment Decomposition (10-K Verified)
A2: All figures in $M unless noted. Blue = hardcoded input (10-K sourced). Black = formula.
B4: FY2023 | C4: FY2024 | D4: FY2025 | E4: FY2026E | F4: FY2027E | G4: Source / Notes
A5: CONSOLIDATED
A6: Total Revenue ($M) | B6: 21997 | C6: 19246 | D6: 18610 | E6: 20100 | F6: 20800 | G6: CLF 10-K FY2025 p.60
A7: Steelmaking Revenue ($M) | B7: 21380 | C7: 18448 | D7: 17953 | E7: 19500 | F7: 20200 | G7: CLF 10-K Note 4 p.75
A8: Other Revenue (mining/elim) ($M) | B8: =B6-B7 -> 617 | C8: =C6-C7 -> 798 | D8: =D6-D7 -> 657 | E8: =E6-E7 -> 600 | F8: =F6-F7 -> 600
A9: Total Shipments (K net tons) | B9: 16367 | C9: 15609 | D9: 16229 | E9: 16500 | F9: 16800 | G9: CLF 10-K MD&A p.46
A10: Average Selling Price ($/ton) | B10: =B7/B9*1000 -> 1306.287 | C10: =C7/C9*1000 -> 1181.8822 | D10: =D7/D9*1000 -> 1106.2296 | E10: =E7/E9*1000 -> 1181.8182 | F10: =F7/F9*1000 -> 1202.381 | G10: Formula: Revenue / Tons
A12: REVENUE BY PRODUCT TYPE — STEELMAKING ($M)
A13: Hot-Rolled | B13: 5789 | C13: 4519 | D13: 4770 | E13: 5100 | F13: 5300 | G13: CLF 10-K Note 4
A14: Cold-Rolled | B14: 2714 | C14: 2410 | D14: 2402 | E14: 2550 | F14: 2650 | G14: CLF 10-K Note 4
A15: Coated | B15: 5874 | C15: 5338 | D15: 5431 | E15: 5700 | F15: 5900 | G15: CLF 10-K Note 4
A16: Stainless & Electrical | B16: 2281 | C16: 1807 | D16: 1748 | E16: 1950 | F16: 2200 | G16: CLF 10-K Note 4 — CRITICAL: $1,748M actual
A17: Plate | B17: 855 | C17: 924 | D17: 1079 | E17: 1100 | F17: 1150 | G17: CLF 10-K Note 4
A18: Slab & Other | B18: 1587 | C18: 1306 | D18: 881 | E18: 500 | F18: 300 | G18: CLF 10-K Note 4; slab contract expired Dec 2025
A19: Other Steelmaking | B19: 2280 | C19: 2144 | D19: 1642 | E19: 1600 | F19: 1700 | G19: CLF 10-K Note 4 (tooling, stamping, etc.)
A20: Total Steelmaking Revenue Check | B20: =SUM(B13:B19) -> 21380 | C20: =SUM(C13:C19) -> 18448 | D20: =SUM(D13:D19) -> 17953 | E20: =SUM(E13:E19) -> 18500 | F20: =SUM(F13:F19) -> 19200 | G20: Should match row 7
A23: SHIPMENTS BY PRODUCT TYPE (K net tons)
A24: Hot-Rolled | B24: 5575 | C24: 5584 | D24: 6484 | E24: 6600 | F24: 6700 | G24: CLF 10-K MD&A p.46
A25: Cold-Rolled | B25: 2361 | C25: 2527 | D25: 2382 | E25: 2450 | F25: 2500 | G25: CLF 10-K MD&A
A26: Coated | B26: 3851 | C26: 4473 | D26: 4486 | E26: 4550 | F26: 4600 | G26: CLF 10-K MD&A
A27: Stainless & Electrical | B27: 510 | C27: 567 | D27: 552 | E27: 570 | F27: 600 | G27: CLF 10-K MD&A — 3.4% of volume, 9.7% of revenue
A28: Plate | B28: 703 | C28: 759 | D28: 863 | E28: 880 | F28: 900 | G28: CLF 10-K MD&A
A29: Slab & Other | B29: 3367 | C29: 1699 | D29: 1462 | E29: 450 | F29: 200 | G29: CLF 10-K MD&A; slab expired
A30: Total Shipments Check | B30: =SUM(B24:B29) -> 16367 | C30: =SUM(C24:C29) -> 15609 | D30: =SUM(D24:D29) -> 16229 | E30: =SUM(E24:E29) -> 15500 | F30: =SUM(F24:F29) -> 15500
A33: IMPLIED ASP BY PRODUCT ($/ton)
A34: S&E Average Selling Price | B34: =B16/B27*1000 -> 4472.549 | C34: =C16/C27*1000 -> 3186.9489 | D34: =D16/D27*1000 -> 3166.6667 | E34: =E16/E27*1000 -> 3421.0526 | F34: =F16/F27*1000 -> 3666.6667 | G34: S&E Rev / S&E Tons × 1000
A35: Blended ASP (excl S&E) | B35: =(B7-B16)/(B9-B27)*1000 -> 1204.4523 | C35: =(C7-C16)/(C9-C27)*1000 -> 1106.3024 | D35: =(D7-D16)/(D9-D27)*1000 -> 1033.6799 | E35: =(E7-E16)/(E9-E27)*1000 -> 1101.6949 | F35: =(F7-F16)/(F9-F27)*1000 -> 1111.1111 | G35: (Total Rev - S&E Rev) / (Total Tons - S&E Tons)
A36: S&E ASP Premium (x Blended) | B36: =B34/B35 -> 3.7133468 | C36: =C34/C35 -> 2.8807214 | D36: =D34/D35 -> 3.0634886 | E36: =E34/E35 -> 3.1052632 | F36: =F34/F35 -> 3.3 | G36: How many x higher is S&E vs blended
A38: REVENUE BY END MARKET — STEELMAKING ($M)
A39: Direct Automotive | B39: 6321 | C39: 5410 | D39: 5047 | E39: 5200 | F39: 5400 | G39: CLF 10-K Note 4
A40: Infrastructure & Manufacturing | B40: 5988 | C40: 5189 | D40: 5377 | E40: 5700 | F40: 6100 | G40: CLF 10-K Note 4; includes transformer/grid
A41: Distributors & Converters | B41: 6272 | C41: 5289 | D41: 5195 | E41: 5300 | F41: 5500 | G41: CLF 10-K Note 4
A42: Steel Producers | B42: 2799 | C42: 2560 | D42: 2334 | E42: 1800 | F42: 1500 | G42: CLF 10-K Note 4; declining w/ slab expiry
A43: Total End Market Check | B43: =SUM(B39:B42) -> 21380 | C43: =SUM(C39:C42) -> 18448 | D43: =SUM(D39:D42) -> 17953 | E43: =SUM(E39:E42) -> 18000 | F43: =SUM(F39:F42) -> 18500

Sheet GOES Segment Isolation
A1: GOES (Grain-Oriented Electrical Steel) — Segment Isolation (10-K Verified)
A2: 10-K Note 4 reveals S&E = $1,748M on 552K tons (FY2025). Previous estimate was $540M — 3.2x too low.
A3: Blue = assumption (editable). Yellow = key assumption. Black = formula.
B5: FY2023 | C5: FY2024 | D5: FY2025 | E5: FY2026E | F5: FY2027E | G5: Source / Notes
A6: STAINLESS & ELECTRICAL — VERIFIED FROM 10-K
A7: S&E Revenue ($M) | B7: 2281 | C7: 1807 | D7: 1748 | E7: 1950 | F7: 2200 | G7: CLF 10-K Note 4 — ACTUAL DISCLOSURE
A8: S&E Shipments (K tons) | B8: 510 | C8: 567 | D8: 552 | E8: 570 | F8: 600 | G8: CLF 10-K MD&A
A9: S&E ASP ($/ton) | B9: =B7/B8*1000 -> 4472.549 | C9: =C7/C8*1000 -> 3186.9489 | D9: =D7/D8*1000 -> 3166.6667 | E9: =E7/E8*1000 -> 3421.0526 | F9: =F7/F8*1000 -> 3666.6667 | G9: Revenue / Tons × 1000
A10: S&E as % of Steelmaking Revenue | B10: =B7/'Revenue Decomposition'!B7 -> 0.10668849 | C10: =C7/'Revenue Decomposition'!C7 -> 0.097950997 | D10: =D7/'Revenue Decomposition'!D7 -> 0.097365343 | E10: =E7/'Revenue Decomposition'!E7 -> 0.1 | F10: =F7/'Revenue Decomposition'!F7 -> 0.10891089
A11: S&E as % of Steelmaking Volume | B11: =B8/'Revenue Decomposition'!B9 -> 0.031160262 | C11: =C8/'Revenue Decomposition'!C9 -> 0.036325197 | D11: =D8/'Revenue Decomposition'!D9 -> 0.034013186 | E11: =E8/'Revenue Decomposition'!E9 -> 0.034545455 | F11: =F8/'Revenue Decomposition'!F9 -> 0.035714286
A13: GOES ISOLATION WITHIN S&E SEGMENT
A14: GOES as % of S&E Revenue | B14: 0.55 | C14: 0.55 | D14: 0.55 | E14: 0.58 | F14: 0.62 | G14: Estimate: GOES is majority of S&E; balance is NOES + auto chrome + stainless
A15: Implied GOES Revenue ($M) | B15: =B7*B14 -> 1254.55 | C15: =C7*C14 -> 993.85 | D15: =D7*D14 -> 961.4 | E15: =E7*E14 -> 1131 | F15: =F7*F14 -> 1364 | G15: S&E Rev × GOES %
A16: GOES ASP ($/ton) — est. premium over S&E | B16: 4200 | C16: 4500 | D16: 4800 | E16: 5200 | F16: 5500 | G16: GOES is highest-ASP within S&E (Hi-B GOES > NOES > stainless)
A17: Implied GOES Volume (K tons) | B17: =B15/B16*1000 -> 298.70238 | C17: =C15/C16*1000 -> 220.85556 | D17: =D15/D16*1000 -> 200.29167 | E17: =E15/E16*1000 -> 217.5 | F17: =F15/F16*1000 -> 248 | G17: GOES Rev / GOES ASP × 1000
A18: NOES + Stainless + Auto Chrome Rev ($M) | B18: =B7-B15 -> 1026.45 | C18: =C7-C15 -> 813.15 | D18: =D7-D15 -> 786.6 | E18: =E7-E15 -> 819 | F18: =F7-F15 -> 836 | G18: Residual: S&E Rev - GOES Rev
A20: GOES MARGIN ESTIMATION
A21: GOES Gross Margin (%) | B21: 0.35 | C21: 0.33 | D21: 0.3 | E21: 0.38 | F21: 0.4 | G21: Specialty steel margins: 30-40%. Protected pricing + tariffs.
A22: GOES Gross Profit ($M) | B22: =B15*B21 -> 439.0925 | C22: =C15*C21 -> 327.9705 | D22: =D15*D21 -> 288.42 | E22: =E15*E21 -> 429.78 | F22: =F15*F21 -> 545.6
A23: GOES SGA Allocation (%) | B23: 0.05 | C23: 0.05 | D23: 0.05 | E23: 0.05 | F23: 0.04 | G23: Lower SGA than carbon: captive demand, no broker/distribution
A24: GOES SGA ($M) | B24: =B15*B23 -> 62.7275 | C24: =C15*C23 -> 49.6925 | D24: =D15*D23 -> 48.07 | E24: =E15*E23 -> 56.55 | F24: =F15*F23 -> 54.56
A25: GOES D&A Allocation ($M) | B25: 60 | C25: 65 | D25: 70 | E25: 75 | F25: 80 | G25: Est. share of $1,204M total D&A (CLF 10-K)
A26: GOES EBITDA ($M) | B26: =B22-B24 -> 376.365 | C26: =C22-C24 -> 278.278 | D26: =D22-D24 -> 240.35 | E26: =E22-E24 -> 373.23 | F26: =F22-F24 -> 491.04 | G26: GP - SGA + D&A addback (D&A is non-cash)
A27: GOES EBITDA Margin (%) | B27: =IF(B15>0,B26/B15,0) -> 0.3 | C27: =IF(C15>0,C26/C15,0) -> 0.28 | D27: =IF(D15>0,D26/D15,0) -> 0.25 | E27: =IF(E15>0,E26/E15,0) -> 0.33 | F27: =IF(F15>0,F26/F15,0) -> 0.36
A29: CARBON STEEL / OTHER — RESIDUAL CALCULATION
A30: Total CLF Adjusted EBITDA ($M) | B30: 1893 | C30: 773 | D30: 37 | E30: 1250 | F30: 1800 | G30: CLF 10-K; FY23 restated. FY26-27E = consensus est.
A31: Carbon Steel EBITDA ($M) | B31: =B30-B26 -> 1516.635 | C31: =C30-C26 -> 494.722 | D31: =D30-D26 -> -203.35 | E31: =E30-E26 -> 876.77 | F31: =F30-F26 -> 1308.96 | G31: Total EBITDA - GOES EBITDA
A32: Carbon Steel Revenue ($M) | B32: ='Revenue Decomposition'!B7-B15 -> 20125.45 | C32: ='Revenue Decomposition'!C7-C15 -> 17454.15 | D32: ='Revenue Decomposition'!D7-D15 -> 16991.6 | E32: ='Revenue Decomposition'!E7-E15 -> 18369 | F32: ='Revenue Decomposition'!F7-F15 -> 18836 | G32: Steelmaking Rev - GOES Rev
A33: Carbon Steel EBITDA Margin (%) | B33: =IF(B32>0,B31/B32,0) -> 0.07535906 | C33: =IF(C32>0,C31/C32,0) -> 0.02834409 | D33: =IF(D32>0,D31/D32,0) -> -0.011967678 | E33: =IF(E32>0,E31/E32,0) -> 0.04773096 | F33: =IF(F32>0,F31/F32,0) -> 0.069492461
A35: KEY FINDING: PREVIOUS MODEL vs 10-K ACTUAL
A36: Previous S&E Revenue Estimate ($M) | D36: 540 | G36: Used 3% revenue mix × $18B = $540M
A37: Actual S&E Revenue (10-K Note 4) | D37: 1748 | G37: The filing shows S&E is 9.7% of steelmaking revenue
A38: Estimation Error | D38: =D37/D36-1 -> 2.237037 | G38: Our old model was 3.2x too low on S&E revenue
A39: Why: S&E is 3.4% of VOLUME but 9.7% of REVENUE | D39: =D7/'Revenue Decomposition'!D7 -> 0.097365343 | G39: ASP is ~$3,167/ton vs blended $1,005/ton = 3.15x premium

Sheet Sum-of-Parts Valuation
A1: Cleveland-Cliffs — Sum-of-Parts Valuation (Updated w/ 10-K Data)
A2: Based on FY2026E EBITDA. Blue = editable assumption.
A4: Segment | B4: FY2026E EBITDA ($M) | C4: Appropriate Multiple | D4: Implied EV ($M) | E4: Multiple Rationale | F4: Comparable Companies | G4: Notes
A5: GOES Electrical Steel (Monopoly) | B5: ='GOES Segment Isolation'!E26 -> 373.23 | C5: 12 | D5: =B5*C5 -> 4478.76 | E5: Sole-source US producer. 80-230% tariff wall. Qualification lock-in. Secular demand: data centers + DOE mandate. | F5: Neo (NEO.TO) 12x; MP Materials 15x; Specialty chemicals 10-14x | G5: Conservative: could justify 14-16x given monopoly + secular demand
A6: Carbon Steel Platform (Commodity) | B6: ='GOES Segment Isolation'!E31 -> 876.77 | C6: 5 | D6: =B6*C6 -> 4383.85 | E6: Commodity steel with 50% Section 232 protection. Cyclical. Leveraged balance sheet warrants peer discount. | F6: Nucor 8x; STLD 7x; US Steel 6x; CLF discount for leverage | G6: Discounted vs peers: B+ credit, $7.3B debt, cyclical trough
A7: Weirton Transformer Plant (Option) | B7: 0 | C7: 0 | D7: 300 | E7: Pre-revenue transformer mfg. Vertical integration into GOES consumption. Online H1 2026. | F7: N/A — option value | G7: Captive GOES demand floor + higher margins on finished transformers
A9: TOTAL ENTERPRISE VALUE (SOP) | B9: =SUM(B5:B7) -> 1250 | D9: =SUM(D5:D7) -> 9162.61
A11: BRIDGE TO EQUITY VALUE
A12: Implied Enterprise Value | B12: =D9 -> 9162.61
A13: Less: Net Debt | B13: -7253 | G13: CLF 10-K: $6,801M senior notes + $452M ABL
A14: Less: Minority Interest / Adjustments | B14: -200 | G14: Stelco minority + pension obligations
A15: Plus: POSCO Strategic Partnership | B15: 700 | G15: MOU signed Q3 2025; expected $700M equity/asset sale
A16: Implied Equity Value ($M) | B16: =B12+B13+B14+B15 -> 2409.61
A17: Shares Outstanding (M) | B17: 570 | G17: CLF 10-K: 569.8M
A18: Implied Share Price | B18: =IF(B17>0,B16/B17,0) -> 4.227386
A19: Current Share Price | B19: 10.66
A20: Upside / (Downside) | B20: =IF(B19>0,B18/B19-1,0) -> -0.60343471
A23: SENSITIVITY: GOES Multiple vs Carbon Steel Multiple
A24: Implied Share Price | B24: CS 4.0x | C24: CS 4.5x | D24: CS 5.0x | E24: CS 5.5x | F24: CS 6.0x
A25: GOES 8.0x | B25: =('GOES Segment Isolation'!E26*8+'GOES Segment Isolation'!E31*4+D7+B13+B14+B15)/B17 -> 0.070035088 | C25: =('GOES Segment Isolation'!E26*8+'GOES Segment Isolation'!E31*4.5+D7+B13+B14+B15)/B17 -> 0.83913158 | D25: =('GOES Segment Isolation'!E26*8+'GOES Segment Isolation'!E31*5+D7+B13+B14+B15)/B17 -> 1.6082281 | E25: =('GOES Segment Isolation'!E26*8+'GOES Segment Isolation'!E31*5.5+D7+B13+B14+B15)/B17 -> 2.3773246 | F25: =('GOES Segment Isolation'!E26*8+'GOES Segment Isolation'!E31*6+D7+B13+B14+B15)/B17 -> 3.1464211
A26: GOES 10.0x | B26: =('GOES Segment Isolation'!E26*10+'GOES Segment Isolation'!E31*4+D7+B13+B14+B15)/B17 -> 1.379614 | C26: =('GOES Segment Isolation'!E26*10+'GOES Segment Isolation'!E31*4.5+D7+B13+B14+B15)/B17 -> 2.1487105 | D26: =('GOES Segment Isolation'!E26*10+'GOES Segment Isolation'!E31*5+D7+B13+B14+B15)/B17 -> 2.917807 | E26: =('GOES Segment Isolation'!E26*10+'GOES Segment Isolation'!E31*5.5+D7+B13+B14+B15)/B17 -> 3.6869035 | F26: =('GOES Segment Isolation'!E26*10+'GOES Segment Isolation'!E31*6+D7+B13+B14+B15)/B17 -> 4.456
A27: GOES 12.0x | B27: =('GOES Segment Isolation'!E26*12+'GOES Segment Isolation'!E31*4+D7+B13+B14+B15)/B17 -> 2.689193 | C27: =('GOES Segment Isolation'!E26*12+'GOES Segment Isolation'!E31*4.5+D7+B13+B14+B15)/B17 -> 3.4582895 | D27: =('GOES Segment Isolation'!E26*12+'GOES Segment Isolation'!E31*5+D7+B13+B14+B15)/B17 -> 4.227386 | E27: =('GOES Segment Isolation'!E26*12+'GOES Segment Isolation'!E31*5.5+D7+B13+B14+B15)/B17 -> 4.9964825 | F27: =('GOES Segment Isolation'!E26*12+'GOES Segment Isolation'!E31*6+D7+B13+B14+B15)/B17 -> 5.7655789
A28: GOES 14.0x | B28: =('GOES Segment Isolation'!E26*14+'GOES Segment Isolation'!E31*4+D7+B13+B14+B15)/B17 -> 3.9987719 | C28: =('GOES Segment Isolation'!E26*14+'GOES Segment Isolation'!E31*4.5+D7+B13+B14+B15)/B17 -> 4.7678684 | D28: =('GOES Segment Isolation'!E26*14+'GOES Segment Isolation'!E31*5+D7+B13+B14+B15)/B17 -> 5.5369649 | E28: =('GOES Segment Isolation'!E26*14+'GOES Segment Isolation'!E31*5.5+D7+B13+B14+B15)/B17 -> 6.3060614 | F28: =('GOES Segment Isolation'!E26*14+'GOES Segment Isolation'!E31*6+D7+B13+B14+B15)/B17 -> 7.0751579
A29: GOES 16.0x | B29: =('GOES Segment Isolation'!E26*16+'GOES Segment Isolation'!E31*4+D7+B13+B14+B15)/B17 -> 5.3083509 | C29: =('GOES Segment Isolation'!E26*16+'GOES Segment Isolation'!E31*4.5+D7+B13+B14+B15)/B17 -> 6.0774474 | D29: =('GOES Segment Isolation'!E26*16+'GOES Segment Isolation'!E31*5+D7+B13+B14+B15)/B17 -> 6.8465439 | E29: =('GOES Segment Isolation'!E26*16+'GOES Segment Isolation'!E31*5.5+D7+B13+B14+B15)/B17 -> 7.6156404 | F29: =('GOES Segment Isolation'!E26*16+'GOES Segment Isolation'!E31*6+D7+B13+B14+B15)/B17 -> 8.3847368

Sheet Transformer Value Chain
A1: Transformer Value Chain — Who Gets Paid What
A2: The market priced transformer DEMAND into OEMs (Eaton 32x). It has NOT priced GOES SUPPLY into CLF (5x).
A4: Company | B4: Ticker | C4: Role in Chain | D4: Mkt Cap ($B) | E4: Rev ($B) | F4: EBITDA ($B) | G4: EV/EBITDA | H4: P/E | I4: Rev Gr YoY | J4: EBITDA Mgn | K4: Backlog / Demand Signal | L4: Priced In?
C5: GOES / INPUT SUPPLIER
A6: Cleveland-Cliffs | B6: CLF | C6: Only US GOES producer (transformer core steel) | D6: 6.1 | E6: 18.6 | F6: 0.037 | G6: N/M (trough) | H6: N/M | I6: -0.031 | J6: 0.002 | K6: Transformer backlog = GOES demand. Every transformer needs GOES. 274% demand growth since 2019. | L6: NOT PRICED IN Market sees "steel cyclical"
C7: TRANSFORMER & POWER DISTRIBUTION OEMs
A8: Eaton | B8: ETN | C8: Distribution transformers, switchgear, UPS, PDUs | D8: 155 | E8: 25.2 | F8: 6.3 | G8: 32.0x | H8: 31.0x | I8: 0.13 | J8: 0.25 | K8: Data center orders +70% Q3 2025. Electrical backlog +29%. | L8: FULLY PRICED At 32x PE, all-time high
A9: Siemens Energy | B9: ENR.DE | C9: Large power transformers, gas turbines, grid tech | D9: 80 | E9: 38 | F9: 4.5 | G9: 18.0x | H9: 25.0x | I9: 0.18 | J9: 0.118 | K9: Record backlog. Building $150M Charlotte LPT factory. | L9: MOSTLY PRICED
A10: Hitachi Energy | B10: 6501.T | C10: Large power transformers, HVDC, grid automation | D10: 95 | E10: 32 | F10: 5 | G10: 19.0x | H10: 28.0x | I10: 0.12 | J10: 0.156 | K10: Investing $1B+ in US capacity. South Boston VA plant. | L10: MOSTLY PRICED
A11: ABB | B11: ABBN.SW | C11: Power transformers, distribution, drives | D11: 95 | E11: 33 | F11: 6 | G11: 16.0x | H11: 24.0x | I11: 0.08 | J11: 0.182 | K11: Electrification segment organic +8%. Grid strong. | L11: PARTIALLY PRICED
C12: OTHER CRITICAL INPUT SUPPLIERS
A13: Freeport-McMoRan | B13: FCX | C13: Copper (30-40% of transformer cost) | D13: 75 | E13: 25.5 | F13: 10.5 | G13: 7.5x | H13: 12.0x | I13: 0.15 | J13: 0.412 | K13: Copper at ATH. Section 232 decision pending. | L13: PARTIALLY PRICED

Sheet The GOES Argument
A1: THE GOES ARGUMENT: Why CLF at 5x Is Mispriced If Eaton at 32x Is Right
A2: Updated with 10-K verified data: S&E = $1,748M (9.7% of revenue on 3.4% of volume)
A4: THE LOGIC CHAIN
A5: 1. AI data centers need electricity | B5: Microsoft, Google, Amazon, Meta collectively planning 50+ GW of new data center capacity
A6: 2. Electricity needs transformers | B6: Every 100MW campus = multiple LPTs + dozens of distribution transformers
A7: 3. Transformer demand is up 274% since 2019 | B7: Wood Mackenzie: 30% supply deficit in power transformers; 2-4 year lead times
A8: 4. The market has priced this into OEMs | B8: Eaton at 32x P/E, all-time high. Siemens record backlog. Hitachi investing $1B+.
A9: 5. Every transformer core is made of GOES | B9: GOES = 30-40% of transformer material cost. No substitute. No alternative material.
A10: 6. CLF is the ONLY US producer of GOES | B10: Butler Works (PA) + Zanesville (OH) + Middletown (OH). Only domestic source. TRAN-COR brand.
A11: 7. Imports face 80-230% effective tariffs | B11: Section 232 (50%) + anti-dumping/CVD (30-180%) = no viable import alternative
A12: 8. CLF trades at 5x EBITDA | B12: Market prices CLF as "leveraged steel cyclical" — assigns $0 to GOES monopoly
A14: THE 10-K REVELATION
A15: S&E is 3.4% of volume but 9.7% of revenue | B15: ASP of ~$3,167/ton vs blended $1,005/ton = 3.15x premium. This is the specialty materials pricing signal.
A16: S&E revenue = $1,748M (FY2025) | B16: Our previous estimate was $540M using volume mix. The 10-K Note 4 product-line disclosure corrects this 3.2x underestimate.
A17: GOES is likely 55-62% of S&E = $961-$1,084M | B17: Even at conservative GOES share, the monopoly business is ~$1B revenue — material to the thesis.
A18: Slab contract expired Dec 9, 2025 | B18: ~1.5M tons/yr at ~10% of volume. Unprofitable. Permanent removal = $500M+ EBITDA tailwind.
A19: Total D&A = $1,204M; Adj EBITDA = $37M | B19: FY2025 was trough. Slab expiry + ASP recovery + tariffs = structural recovery, not cyclical hope.
A21: THE DISCONNECT
A22: Eaton at 32x says: | B22: "Transformer demand is exploding and will continue for years"
A23: CLF at 5x says: | B23: "This is just a cyclical steel company with too much debt"
A24: Both cannot be right. | B24: If Eaton is correct, then the sole-source supplier of the critical input material cannot be worth 5x.
A26: WHAT THE GOES MONOPOLY IS WORTH (UPDATED)
A27: GOES Revenue (est. 55% of $1,748M S&E): | B27: ~$961M — a material, near-billion-dollar business hidden inside a steel company
A28: GOES EBITDA at 30% margin: | B28: ~$288M operating EBITDA from the monopoly segment alone
A29: At 12x EBITDA (specialty materials peer avg): | B29: GOES segment alone = ~$3.5B enterprise value
A30: CLF total current EV: | B30: ~$13.4B ($6.1B market cap + $7.3B net debt)
A31: GOES as % of current EV: | B31: ~26% at 12x — and the market is assigning it near 0%
A33: CATALYSTS TO FORCE RECOGNITION
A34: Q1 2026 Earnings (April 17) | B34: First clean quarter without slab drag. EBITDA recovery should be visible. Make-or-break print.
A35: POSCO Definitive Agreement | B35: $700M cash for deleveraging. Strategic validation from world #3 steelmaker.
A36: DOE Transformer Efficiency Mandate | B36: April 2029 compliance date. Creates regulatory pull for Hi-B GOES. CLF is only US source.
A37: Weirton Transformer Plant | B37: Vertical integration forward. CLF becomes GOES producer AND transformer manufacturer.
A38: Analyst Initiation with GOES Thesis | B38: Once the Street models GOES separately, re-rating follows. Currently 0 analysts model this way.

Sheet 10-K Data Extract
A1: CLF 10-K FY2025 — Key Data Points Extracted
A2: Source: CLF Form 10-K for fiscal year ended December 31, 2025 (filed Feb 2026)
A4: Data Point | B4: Value | C4: Page / Note | D4: Context
A5: CONSOLIDATED FINANCIALS
A6: Total Revenue | B6: $18,610M | C6: p.60 | D6: Down from $19,246M (FY2024)
A7: Steelmaking Revenue | B7: $18,063M | C7: Note 5, p.84 | D7: Includes intercompany eliminations
A8: Net Loss | B8: ($1,428M) | C8: p.60 | D8: vs ($714M) FY2024
A9: Adjusted EBITDA | B9: $37M | C9: p.55 | D9: vs $773M FY2024; trough year
A10: D&A | B10: $1,235M | C10: p.52 | D10: Up from $951M; Stelco + idle facilities
A11: Total Long-Term Debt | B11: $7,253M | C11: p.64 | D11: Senior notes $6,801M + ABL $452M
A12: Shares Outstanding | B12: 569.8M | C12: p.60 | D12: Diluted shares for EPS calculation
A13: Cash | B13: $57M | C13: p.55 | D13: Plus ABL availability = $3.3B total liquidity
A15: PRODUCT LINE REVENUE (Note 4)
A16: Hot-Rolled Revenue | B16: $4,770M | C16: Note 4, p.75
A17: Cold-Rolled Revenue | B17: $2,402M | C17: Note 4, p.75
A18: Coated Revenue | B18: $5,431M | C18: Note 4, p.75
A19: STAINLESS & ELECTRICAL Revenue | B19: $1,748M | C19: Note 4, p.75 | D19: KEY: was $2,281M (FY23), $1,807M (FY24)
A20: Plate Revenue | B20: $1,079M | C20: Note 4, p.75
A21: Slab & Other Revenue | B21: $881M | C21: Note 4, p.75 | D21: Down from $1,306M; slab contract winding down
A22: Other Steelmaking Revenue | B22: $1,642M | C22: Note 4, p.75
A24: SHIPMENTS (K net tons)
A25: Hot-Rolled | B25: 6,484 | C25: MD&A p.46 | D25: Up 16% YoY
A26: Cold-Rolled | B26: 2,382 | C26: MD&A p.46 | D26: Down 6%
A27: Coated | B27: 4,486 | C27: MD&A p.46 | D27: Flat
A28: Stainless & Electrical | B28: 552 | C28: MD&A p.46 | D28: Down 3% from 567; 3.4% of total volume
A29: Plate | B29: 863 | C29: MD&A p.46 | D29: Up 14%
A30: Slab & Other | B30: 1,462 | C30: MD&A p.46 | D30: Down 13%; slab contract expiring
A31: Total | B31: 16,229 | C31: MD&A p.46 | D31: Up 4% including Stelco
A33: SLAB CONTRACT
A34: Volume | B34: ~1.5M tons/yr | C34: p.7 | D34: ~10% of sales volume
A35: Pricing | B35: Brazilian slab export | C35: p.15 | D35: Negatively impacted by tariffs
A36: Profitability | B36: Unprofitable 2024-2025 | C36: p.7 | D36: This is the $500M+ EBITDA swing
A37: Expiration | B37: December 9, 2025 | C37: p.7 | D37: EXPIRED — NOT RENEWED
A39: GOES / ELECTRICAL STEEL FACILITIES
A40: Butler Works (PA) | B40: EAF, 0.3M nt | C40: p.33 | D40: Primary GOES facility
A41: Middletown (OH) | B41: BF-BOF, 2.7M nt | C41: p.33 | D41: S&E processing capability
A42: Zanesville (OH) | B42: S&E processing | C42: p.33 | D42: Finishing facility
A43: Coshocton (OH) | B43: New bright anneal line | C43: p.4 | D43: Commissioned 2025; GOES quality improvement
A45: KEY RATIOS (IMPLIED)
A46: S&E ASP | B46: ~$3,167/ton | C46: Calc | D46: $1,748M / 552K tons — 3.15x blended ASP
...
